Workbook

Sheet DCA-Anexo I-AB
A2: QDCC
A3: BALANÇO ANUAL (DCA)
A4: VERSÃO: v14
A5: VIGÊNCIA: 05/01/2026
A7: Ente: 2908101 - Cocos/BA
A8: Poder: E - Executivo
A9: Instituição: 4063 - Prefeitura Municipal de Cocos - BA
A10: Exercício: 2025
A11: Periodicidade: ANUAL
A12: Período: Período único (anual)
A14: Grupo: Balanço Patrimonial - Ativo e Passivo
A15: Quadro: Balanço Patrimonial
A16: Rótulo: Padrão
A17: Balanço Patrimonial | B17: Valores
B18: 31/12/2025
A19: Ativo
A20: Ativo
A21: 1.0.0.0.0.00.00 - Ativo | B21: =+'DCA-Anexo I-AB'!B22+'DCA-Anexo I-AB'!B227 -> 54031265
A22: 1.1.0.0.0.00.00 - Ativo Circulante | B22: =+'DCA-Anexo I-AB'!B23+'DCA-Anexo I-AB'!B32+'DCA-Anexo I-AB'!B75+'DCA-Anexo I-AB'!B124+'DCA-Anexo I-AB'!B135+'DCA-Anexo I-AB'!B152+'DCA-Anexo I-AB'!B172+'DCA-Anexo I-AB'!B169 -> 11601960
A23: 1.1.1.0.0.00.00 - Caixa e Equivalentes de Caixa | B23: =+'DCA-Anexo I-AB'!B24+'DCA-Anexo I-AB'!B27+'DCA-Anexo I-AB'!B29 -> 7883059.6
A24: 1.1.1.1.0.00.00 - Caixa e Equivalentes de Caixa em Moeda Nacional | B24: =+'DCA-Anexo I-AB'!B25+'DCA-Anexo I-AB'!B26 -> 7883059.6
A25: 1.1.1.1.1.00.00 - Caixa e Equivalentes de Caixa em Moeda Nacional - Consolidação | B25: 7883059.6
A26: 1.1.1.1.2.00.00 - Caixa e Equivalentes de Caixa em Moeda Nacional - Intra OFSS
A27: 1.1.1.2.0.00.00 - Caixa e Equivalentes de Caixa em Moeda Estrangeira | B27: =+'DCA-Anexo I-AB'!B28 -> 0
A28: 1.1.1.2.1.00.00 - Caixa e Equivalentes de Caixa em Moeda Estrangeira - Consolidação
A29: 1.1.1.3.0.00.00 - Caixa e Equivalentes de Caixa - Valores Restituíveis e Vinculados | B29: =+'DCA-Anexo I-AB'!B30+'DCA-Anexo I-AB'!B31 -> 0
A30: 1.1.1.3.1.00.00 - Depósitos Restituíveis e Valores Vinculados - Consolidação
A31: 1.1.1.3.2.00.00 - Valores Restituíveis - Intra OFSS
A32: 1.1.2.0.0.00.00 - Créditos a Curto Prazo | B32: =+'DCA-Anexo I-AB'!B33+'DCA-Anexo I-AB'!B39+'DCA-Anexo I-AB'!B45+'DCA-Anexo I-AB'!B51+'DCA-Anexo I-AB'!B57+'DCA-Anexo I-AB'!B63-'DCA-Anexo I-AB'!B69 -> 3718900.3
A33: 1.1.2.1.0.00.00 - Créditos Tributários a Receber | B33: =+'DCA-Anexo I-AB'!B34+'DCA-Anexo I-AB'!B35+'DCA-Anexo I-AB'!B36+'DCA-Anexo I-AB'!B37+'DCA-Anexo I-AB'!B38 -> 1647985.1
A34: 1.1.2.1.1.00.00 - Créditos Tributários a Receber - Consolidação | B34: 1647985.1
A35: 1.1.2.1.2.00.00 - Créditos Tributários a Receber - Intra OFSS
A36: 1.1.2.1.3.00.00 - Créditos Tributários a Receber - Inter OFSS - União
A37: 1.1.2.1.4.00.00 - Créditos Tributários a Receber - Inter OFSS – Estado
A38: 1.1.2.1.5.00.00 - Créditos Tributários a Receber - Inter OFSS - Município
A39: 1.1.2.2.0.00.00 - Clientes | B39: =+'DCA-Anexo I-AB'!B40+'DCA-Anexo I-AB'!B41+'DCA-Anexo I-AB'!B42+'DCA-Anexo I-AB'!B43+'DCA-Anexo I-AB'!B44 -> 0
A40: 1.1.2.2.1.00.00 - Clientes - Consolidação
A41: 1.1.2.2.2.00.00 - Clientes - Intra OFSS
A42: 1.1.2.2.3.00.00 - Clientes - Inter OFSS - União
A43: 1.1.2.2.4.00.00 - Clientes - Inter OFSS - Estado
...

Sheet formulas
A1: [DCA-Anexo I-AB]
A2: 'DCA-Anexo I-AB'!B22=+'DCA-Anexo I-AB'!B23+'DCA-Anexo I-AB'!B32+'DCA-Anexo I-AB'!B75+'DCA-Anexo I-AB'!B124+'DCA-Anexo I-AB'!B135+'DCA-Anexo I-AB'!B152+'DCA-Anexo I-AB'!B172+'DCA-Anexo I-AB'!B169
A3: 'DCA-Anexo I-AB'!B23=+'DCA-Anexo I-AB'!B24+'DCA-Anexo I-AB'!B27+'DCA-Anexo I-AB'!B29
A4: 'DCA-Anexo I-AB'!B24=+'DCA-Anexo I-AB'!B25+'DCA-Anexo I-AB'!B26
A5: 'DCA-Anexo I-AB'!B27=+'DCA-Anexo I-AB'!B28
A6: 'DCA-Anexo I-AB'!B32=+'DCA-Anexo I-AB'!B33+'DCA-Anexo I-AB'!B39+'DCA-Anexo I-AB'!B45+'DCA-Anexo I-AB'!B51+'DCA-Anexo I-AB'!B57+'DCA-Anexo I-AB'!B63-'DCA-Anexo I-AB'!B69
A7: 'DCA-Anexo I-AB'!B33=+'DCA-Anexo I-AB'!B34+'DCA-Anexo I-AB'!B35+'DCA-Anexo I-AB'!B36+'DCA-Anexo I-AB'!B37+'DCA-Anexo I-AB'!B38
A8: 'DCA-Anexo I-AB'!B39=+'DCA-Anexo I-AB'!B40+'DCA-Anexo I-AB'!B41+'DCA-Anexo I-AB'!B42+'DCA-Anexo I-AB'!B43+'DCA-Anexo I-AB'!B44
A9: 'DCA-Anexo I-AB'!B45=+'DCA-Anexo I-AB'!B46+'DCA-Anexo I-AB'!B47+'DCA-Anexo I-AB'!B48+'DCA-Anexo I-AB'!B49+'DCA-Anexo I-AB'!B50
A10: 'DCA-Anexo I-AB'!B51=+'DCA-Anexo I-AB'!B52+'DCA-Anexo I-AB'!B53+'DCA-Anexo I-AB'!B54+'DCA-Anexo I-AB'!B55+'DCA-Anexo I-AB'!B56
A11: 'DCA-Anexo I-AB'!B57=+'DCA-Anexo I-AB'!B58+'DCA-Anexo I-AB'!B59+'DCA-Anexo I-AB'!B60+'DCA-Anexo I-AB'!B61+'DCA-Anexo I-AB'!B62
A12: 'DCA-Anexo I-AB'!B63=+'DCA-Anexo I-AB'!B64+'DCA-Anexo I-AB'!B65+'DCA-Anexo I-AB'!B66+'DCA-Anexo I-AB'!B67+'DCA-Anexo I-AB'!B68
... A2455: 'DCA-Anexo I-E'!F204=+'DCA-Anexo I-E'!F205+'DCA-Anexo I-E'!F206+'DCA-Anexo I-E'!F207+'DCA-Anexo I-E'!F208+'DCA-Anexo I-E'!F209+'DCA-Anexo I-E'!F210+'DCA-Anexo I-E'!F211+'DCA-Anexo I-E'!F212

Sheet DCA-Anexo I-C
A2: QDCC
A3: BALANÇO ANUAL (DCA)
A4: VERSÃO: v14
A5: VIGÊNCIA: 05/01/2026
A7: Ente: 2908101 - Cocos/BA
A8: Poder: E - Executivo
A9: Instituição: 4063 - Prefeitura Municipal de Cocos - BA
A10: Exercício: 2025
A11: Periodicidade: ANUAL
A12: Período: Período único (anual)
A14: Grupo: Balanço Orçamentário - Receitas Orçamentárias
A15: Quadro: Receitas Orçamentárias
A16: Rótulo: Padrão
A17: Receitas Orçamentárias | B17: Execução da Receita
B18: Receitas Brutas Realizadas | C18: Deduções - Transferências Constitucionais | D18: Deduções - FUNDEB | E18: Outras Deduções da Receita
A19: Receitas Orçamentárias
A20: RECEITAS (EXCETO INTRA-ORÇAMENTÁRIAS) (I) | B20: =+'DCA-Anexo I-C'!B21+'DCA-Anexo I-C'!B690 -> 1.5097371e+08 | C20: =+'DCA-Anexo I-C'!C21+'DCA-Anexo I-C'!C690 -> 0 | D20: =+'DCA-Anexo I-C'!D21+'DCA-Anexo I-C'!D690 -> 15193653 | E20: =+'DCA-Anexo I-C'!E21+'DCA-Anexo I-C'!E690 -> 0
A21: 1.0.0.0.00.0.0 - Receitas Correntes | B21: =+'DCA-Anexo I-C'!B22+'DCA-Anexo I-C'!B90+'DCA-Anexo I-C'!B253+'DCA-Anexo I-C'!B378+'DCA-Anexo I-C'!B379+'DCA-Anexo I-C'!B380+'DCA-Anexo I-C'!B417+'DCA-Anexo I-C'!B551 -> 1.4973449e+08 | C21: =+'DCA-Anexo I-C'!C22+'DCA-Anexo I-C'!C90+'DCA-Anexo I-C'!C253+'DCA-Anexo I-C'!C378+'DCA-Anexo I-C'!C379+'DCA-Anexo I-C'!C380+'DCA-Anexo I-C'!C417+'DCA-Anexo I-C'!C551 -> 0 | D21: =+'DCA-Anexo I-C'!D22+'DCA-Anexo I-C'!D90+'DCA-Anexo I-C'!D253+'DCA-Anexo I-C'!D378+'DCA-Anexo I-C'!D379+'DCA-Anexo I-C'!D380+'DCA-Anexo I-C'!D417+'DCA-Anexo I-C'!D551 -> 15193653 | E21: =+'DCA-Anexo I-C'!E22+'DCA-Anexo I-C'!E90+'DCA-Anexo I-C'!E253+'DCA-Anexo I-C'!E378+'DCA-Anexo I-C'!E379+'DCA-Anexo I-C'!E380+'DCA-Anexo I-C'!E417+'DCA-Anexo I-C'!E551 -> 0
A22: 1.1.0.0.00.0.0 - Impostos, Taxas e Contribuições de Melhoria | B22: =+'DCA-Anexo I-C'!B23+'DCA-Anexo I-C'!B59+'DCA-Anexo I-C'!B83 -> 9603959.8 | C22: =+'DCA-Anexo I-C'!C23+'DCA-Anexo I-C'!C59+'DCA-Anexo I-C'!C83 -> 0 | D22: =+'DCA-Anexo I-C'!D23+'DCA-Anexo I-C'!D59+'DCA-Anexo I-C'!D83 -> 0 | E22: =+'DCA-Anexo I-C'!E23+'DCA-Anexo I-C'!E59+'DCA-Anexo I-C'!E83 -> 0
A23: 1.1.1.0.00.0.0 - Impostos | B23: =+'DCA-Anexo I-C'!B24+'DCA-Anexo I-C'!B27+'DCA-Anexo I-C'!B33+'DCA-Anexo I-C'!B41+'DCA-Anexo I-C'!B55+'DCA-Anexo I-C'!B58 -> 9413468.2 | C23: =+'DCA-Anexo I-C'!C24+'DCA-Anexo I-C'!C27+'DCA-Anexo I-C'!C33+'DCA-Anexo I-C'!C41+'DCA-Anexo I-C'!C55+'DCA-Anexo I-C'!C58 -> 0 | D23: =+'DCA-Anexo I-C'!D24+'DCA-Anexo I-C'!D27+'DCA-Anexo I-C'!D33+'DCA-Anexo I-C'!D41+'DCA-Anexo I-C'!D55+'DCA-Anexo I-C'!D58 -> 0 | E23: =+'DCA-Anexo I-C'!E24+'DCA-Anexo I-C'!E27+'DCA-Anexo I-C'!E33+'DCA-Anexo I-C'!E41+'DCA-Anexo I-C'!E55+'DCA-Anexo I-C'!E58 -> 0
A24: 1.1.1.1.00.0.0 - Impostos sobre o Comércio Exterior | B24: =+'DCA-Anexo I-C'!B25+'DCA-Anexo I-C'!B26 -> 0 | C24: =+'DCA-Anexo I-C'!C25+'DCA-Anexo I-C'!C26 -> 0 | D24: =+'DCA-Anexo I-C'!D25+'DCA-Anexo I-C'!D26 -> 0 | E24: =+'DCA-Anexo I-C'!E25+'DCA-Anexo I-C'!E26 -> 0
A25: 1.1.1.1.01.0.0 - Imposto sobre a Importação
A26: 1.1.1.1.02.0.0 - Imposto sobre a Exportação
A27: 1.1.1.2.00.0.0 - Impostos sobre o Patrimônio | B27: =+'DCA-Anexo I-C'!B28+'DCA-Anexo I-C'!B29+'DCA-Anexo I-C'!B30+'DCA-Anexo I-C'!B31+'DCA-Anexo I-C'!B32 -> 809281.85 | C27: =+'DCA-Anexo I-C'!C28+'DCA-Anexo I-C'!C29+'DCA-Anexo I-C'!C30+'DCA-Anexo I-C'!C31+'DCA-Anexo I-C'!C32 -> 0 | D27: =+'DCA-Anexo I-C'!D28+'DCA-Anexo I-C'!D29+'DCA-Anexo I-C'!D30+'DCA-Anexo I-C'!D31+'DCA-Anexo I-C'!D32 -> 0 | E27: =+'DCA-Anexo I-C'!E28+'DCA-Anexo I-C'!E29+'DCA-Anexo I-C'!E30+'DCA-Anexo I-C'!E31+'DCA-Anexo I-C'!E32 -> 0
A28: 1.1.1.2.01.0.0 - Imposto sobre a Propriedade Territorial Rural
A29: 1.1.1.2.50.0.0 - Imposto sobre a Propriedade Predial e Territorial Urbana | B29: 146001.28
A30: 1.1.1.2.51.0.0 - Imposto sobre a Propriedade de Veículos Automotores
A31: 1.1.1.2.52.0.0 - Imposto sobre Transmissão “Causa Mortis” e Doação de Bens e Direitos
A32: 1.1.1.2.53.0.0 - Impostos sobre Transmissão "Inter Vivos" de Bens Imóveis e de Direitos Reais sobre Imóveis | B32: 663280.57
A33: 1.1.1.3.00.0.0 - Impostos sobre a Renda e Proventos de Qualquer Natureza | B33: =+'DCA-Anexo I-C'!B34+'DCA-Anexo I-C'!B35+'DCA-Anexo I-C'!B36 -> 2414848.6 | C33: =+'DCA-Anexo I-C'!C34+'DCA-Anexo I-C'!C35+'DCA-Anexo I-C'!C36 -> 0 | D33: =+'DCA-Anexo I-C'!D34+'DCA-Anexo I-C'!D35+'DCA-Anexo I-C'!D36 -> 0 | E33: =+'DCA-Anexo I-C'!E34+'DCA-Anexo I-C'!E35+'DCA-Anexo I-C'!E36 -> 0
A34: 1.1.1.3.01.0.0 - Imposto sobre a Renda de Pessoa Física - IRPF
A35: 1.1.1.3.02.0.0 - Imposto sobre a Renda de Pessoa Jurídica - IRPJ - Líquida de Incentivos
A36: 1.1.1.3.03.0.0 - Imposto sobre a Renda - Retido na Fonte | B36: =+'DCA-Anexo I-C'!B37+'DCA-Anexo I-C'!B38+'DCA-Anexo I-C'!B39+'DCA-Anexo I-C'!B40 -> 2414848.6 | C36: =+'DCA-Anexo I-C'!C37+'DCA-Anexo I-C'!C38+'DCA-Anexo I-C'!C39+'DCA-Anexo I-C'!C40 -> 0 | D36: =+'DCA-Anexo I-C'!D37+'DCA-Anexo I-C'!D38+'DCA-Anexo I-C'!D39+'DCA-Anexo I-C'!D40 -> 0 | E36: =+'DCA-Anexo I-C'!E37+'DCA-Anexo I-C'!E38+'DCA-Anexo I-C'!E39+'DCA-Anexo I-C'!E40 -> 0
A37: 1.1.1.3.03.1.0 - Imposto sobre a Renda - Retido na Fonte - Trabalho | B37: 581523.18
A38: 1.1.1.3.03.2.0 - Imposto sobre a Renda - Retido na Fonte - Capital
A39: 1.1.1.3.03.3.0 - Imposto sobre a Renda - Retido na Fonte - Remessa ao Exterior
A40: 1.1.1.3.03.4.0 - Imposto sobre a Renda - Retido na Fonte - Outros Rendimentos | B40: 1833325.4
A41: 1.1.1.4.00.0.0 - Impostos sobre a Produção e Circulação de Mercadorias e Serviços | B41: =+'DCA-Anexo I-C'!B42+'DCA-Anexo I-C'!B48+'DCA-Anexo I-C'!B51+'DCA-Anexo I-C'!B54 -> 6189337.8 | C41: =+'DCA-Anexo I-C'!C42+'DCA-Anexo I-C'!C48+'DCA-Anexo I-C'!C51+'DCA-Anexo I-C'!C54 -> 0 | D41: =+'DCA-Anexo I-C'!D42+'DCA-Anexo I-C'!D48+'DCA-Anexo I-C'!D51+'DCA-Anexo I-C'!D54 -> 0 | E41: =+'DCA-Anexo I-C'!E42+'DCA-Anexo I-C'!E48+'DCA-Anexo I-C'!E51+'DCA-Anexo I-C'!E54 -> 0
A42: 1.1.1.4.01.0.0 - Imposto sobre Produtos Industrializados - IPI | B42: =+'DCA-Anexo I-C'!B43+'DCA-Anexo I-C'!B44+'DCA-Anexo I-C'!B45+'DCA-Anexo I-C'!B46+'DCA-Anexo I-C'!B47 -> 0 | C42: =+'DCA-Anexo I-C'!C43+'DCA-Anexo I-C'!C44+'DCA-Anexo I-C'!C45+'DCA-Anexo I-C'!C46+'DCA-Anexo I-C'!C47 -> 0 | D42: =+'DCA-Anexo I-C'!D43+'DCA-Anexo I-C'!D44+'DCA-Anexo I-C'!D45+'DCA-Anexo I-C'!D46+'DCA-Anexo I-C'!D47 -> 0 | E42: =+'DCA-Anexo I-C'!E43+'DCA-Anexo I-C'!E44+'DCA-Anexo I-C'!E45+'DCA-Anexo I-C'!E46+'DCA-Anexo I-C'!E47 -> 0
A43: 1.1.1.4.01.1.0 - Imposto sobre Produtos Industrializados - IPI - Fumo
...

Sheet DCA-Anexo I-D
A2: QDCC
A3: BALANÇO ANUAL (DCA)
A4: VERSÃO: v14
A5: VIGÊNCIA: 05/01/2026
A7: Ente: 2908101 - Cocos/BA
A8: Poder: E - Executivo
A9: Instituição: 4063 - Prefeitura Municipal de Cocos - BA
A10: Exercício: 2025
A11: Periodicidade: ANUAL
A12: Período: Período único (anual)
A14: Grupo: Balanço Orçamentário - Despesas Orçamentárias
A15: Quadro: Despesas Orçamentárias
A16: Rótulo: Padrão
A17: Despesas Orçamentárias | B17: Execução da Despesa
B18: Despesas Empenhadas | C18: Despesas Liquidadas | D18: Despesas Pagas | E18: Inscrição de Restos a Pagar Não Processados | F18: Inscrição de Restos a Pagar Processados
A19: Despesas Orçamentárias
A20: Total Geral da Despesa | B20: =+'DCA-Anexo I-D'!B21+'DCA-Anexo I-D'!B235 -> 145272093 | C20: =+'DCA-Anexo I-D'!C21+'DCA-Anexo I-D'!C235 -> 145272093 | D20: =+'DCA-Anexo I-D'!D21+'DCA-Anexo I-D'!D235 -> 1.3632376e+08 | E20: =+'DCA-Anexo I-D'!E21+'DCA-Anexo I-D'!E235 -> 0 | F20: =+'DCA-Anexo I-D'!F21+'DCA-Anexo I-D'!F235 -> 8948337.3
A21: 3.0.00.00.00 - Despesas Correntes | B21: =+'DCA-Anexo I-D'!B22+'DCA-Anexo I-D'!B145+'DCA-Anexo I-D'!B103 -> 1.3482931e+08 | C21: =+'DCA-Anexo I-D'!C22+'DCA-Anexo I-D'!C145+'DCA-Anexo I-D'!C103 -> 1.3482931e+08 | D21: =+'DCA-Anexo I-D'!D22+'DCA-Anexo I-D'!D145+'DCA-Anexo I-D'!D103 -> 1.2590038e+08 | E21: =+'DCA-Anexo I-D'!E22+'DCA-Anexo I-D'!E145+'DCA-Anexo I-D'!E103 -> 0 | F21: =+'DCA-Anexo I-D'!F22+'DCA-Anexo I-D'!F145+'DCA-Anexo I-D'!F103 -> 8928935.3
A22: 3.1.00.00.00 - Pessoal e Encargos Sociais | B22: =+'DCA-Anexo I-D'!B34+'DCA-Anexo I-D'!B45+'DCA-Anexo I-D'!B36+'DCA-Anexo I-D'!B46+'DCA-Anexo I-D'!B37+'DCA-Anexo I-D'!B26+'DCA-Anexo I-D'!B100+'DCA-Anexo I-D'!B98+'DCA-Anexo I-D'!B31+'DCA-Anexo I-D'!B23+'DCA-Anexo I-D'!B102+'DCA-Anexo I-D'!B24+'DCA-Anexo I-D'!B75+'DCA-Anexo I-D'!B32+'DCA-Anexo I-D'!B99+'DCA-Anexo I-D'!B44+'DCA-Anexo I-D'!B25+'DCA-Anexo I-D'!B27+'DCA-Anexo I-D'!B101+'DCA-Anexo I-D'!B28+'DCA-Anexo I-D'!B40+'DCA-Anexo I-D'!B38+'DCA-Anexo I-D'!B35+'DCA-Anexo I-D'!B39+'DCA-Anexo I-D'!B30+'DCA-Anexo I-D'!B33+'DCA-Anexo I-D'!B43+'DCA-Anexo I-D'!B29+'DCA-Anexo I-D'!B42+'DCA-Anexo I-D'!B41+'DCA-Anexo I-D'!B97 -> 59121162 | C22: =+'DCA-Anexo I-D'!C34+'DCA-Anexo I-D'!C45+'DCA-Anexo I-D'!C36+'DCA-Anexo I-D'!C46+'DCA-Anexo I-D'!C37+'DCA-Anexo I-D'!C26+'DCA-Anexo I-D'!C100+'DCA-Anexo I-D'!C98+'DCA-Anexo I-D'!C31+'DCA-Anexo I-D'!C23+'DCA-Anexo I-D'!C102+'DCA-Anexo I-D'!C24+'DCA-Anexo I-D'!C75+'DCA-Anexo I-D'!C32+'DCA-Anexo I-D'!C99+'DCA-Anexo I-D'!C44+'DCA-Anexo I-D'!C25+'DCA-Anexo I-D'!C27+'DCA-Anexo I-D'!C101+'DCA-Anexo I-D'!C28+'DCA-Anexo I-D'!C40+'DCA-Anexo I-D'!C38+'DCA-Anexo I-D'!C35+'DCA-Anexo I-D'!C39+'DCA-Anexo I-D'!C30+'DCA-Anexo I-D'!C33+'DCA-Anexo I-D'!C43+'DCA-Anexo I-D'!C29+'DCA-Anexo I-D'!C42+'DCA-Anexo I-D'!C41+'DCA-Anexo I-D'!C97 -> 59121162 | D22: =+'DCA-Anexo I-D'!D34+'DCA-Anexo I-D'!D45+'DCA-Anexo I-D'!D36+'DCA-Anexo I-D'!D46+'DCA-Anexo I-D'!D37+'DCA-Anexo I-D'!D26+'DCA-Anexo I-D'!D100+'DCA-Anexo I-D'!D98+'DCA-Anexo I-D'!D31+'DCA-Anexo I-D'!D23+'DCA-Anexo I-D'!D102+'DCA-Anexo I-D'!D24+'DCA-Anexo I-D'!D75+'DCA-Anexo I-D'!D32+'DCA-Anexo I-D'!D99+'DCA-Anexo I-D'!D44+'DCA-Anexo I-D'!D25+'DCA-Anexo I-D'!D27+'DCA-Anexo I-D'!D101+'DCA-Anexo I-D'!D28+'DCA-Anexo I-D'!D40+'DCA-Anexo I-D'!D38+'DCA-Anexo I-D'!D35+'DCA-Anexo I-D'!D39+'DCA-Anexo I-D'!D30+'DCA-Anexo I-D'!D33+'DCA-Anexo I-D'!D43+'DCA-Anexo I-D'!D29+'DCA-Anexo I-D'!D42+'DCA-Anexo I-D'!D41+'DCA-Anexo I-D'!D97 -> 58738355 | E22: =+'DCA-Anexo I-D'!E34+'DCA-Anexo I-D'!E45+'DCA-Anexo I-D'!E36+'DCA-Anexo I-D'!E46+'DCA-Anexo I-D'!E37+'DCA-Anexo I-D'!E26+'DCA-Anexo I-D'!E100+'DCA-Anexo I-D'!E98+'DCA-Anexo I-D'!E31+'DCA-Anexo I-D'!E23+'DCA-Anexo I-D'!E102+'DCA-Anexo I-D'!E24+'DCA-Anexo I-D'!E75+'DCA-Anexo I-D'!E32+'DCA-Anexo I-D'!E99+'DCA-Anexo I-D'!E44+'DCA-Anexo I-D'!E25+'DCA-Anexo I-D'!E27+'DCA-Anexo I-D'!E101+'DCA-Anexo I-D'!E28+'DCA-Anexo I-D'!E40+'DCA-Anexo I-D'!E38+'DCA-Anexo I-D'!E35+'DCA-Anexo I-D'!E39+'DCA-Anexo I-D'!E30+'DCA-Anexo I-D'!E33+'DCA-Anexo I-D'!E43+'DCA-Anexo I-D'!E29+'DCA-Anexo I-D'!E42+'DCA-Anexo I-D'!E41+'DCA-Anexo I-D'!E97 -> 0 | F22: =+'DCA-Anexo I-D'!F34+'DCA-Anexo I-D'!F45+'DCA-Anexo I-D'!F36+'DCA-Anexo I-D'!F46+'DCA-Anexo I-D'!F37+'DCA-Anexo I-D'!F26+'DCA-Anexo I-D'!F100+'DCA-Anexo I-D'!F98+'DCA-Anexo I-D'!F31+'DCA-Anexo I-D'!F23+'DCA-Anexo I-D'!F102+'DCA-Anexo I-D'!F24+'DCA-Anexo I-D'!F75+'DCA-Anexo I-D'!F32+'DCA-Anexo I-D'!F99+'DCA-Anexo I-D'!F44+'DCA-Anexo I-D'!F25+'DCA-Anexo I-D'!F27+'DCA-Anexo I-D'!F101+'DCA-Anexo I-D'!F28+'DCA-Anexo I-D'!F40+'DCA-Anexo I-D'!F38+'DCA-Anexo I-D'!F35+'DCA-Anexo I-D'!F39+'DCA-Anexo I-D'!F30+'DCA-Anexo I-D'!F33+'DCA-Anexo I-D'!F43+'DCA-Anexo I-D'!F29+'DCA-Anexo I-D'!F42+'DCA-Anexo I-D'!F41+'DCA-Anexo I-D'!F97 -> 382806.31
A23: 3.1.20.00.00 - Transferências à União
A24: 3.1.22.00.00 - Execução orçamentária delegada à União
A25: 3.1.30.00.00 - Transferências a Estados e ao Distrito Federal
A26: 3.1.31.00.00 - Transferências a Estados e ao Distrito Federal - fundo a fundo
A27: 3.1.32.00.00 - Execução orçamentária delegada a Estados e ao Distrito Federal
A28: 3.1.35.00.00 - Transferências fundo a fundo aos Estados e ao Distrito Federal à conta de recursos de que tratam os §§ 1º e 2º do art. 24 da Lei Complementar nº 141, de 2012 - Restos a Pagar Cancelados
A29: 3.1.36.00.00 - Transferências fundo a fundo aos Estados e ao Distrito Federal à conta de recursos de que trata o art. 25 da Lei Complementar nº 141, de 2012 - diferença do mínimo não aplicado em exercícios anteriores
A30: 3.1.40.00.00 - Transferências a Municípios
A31: 3.1.41.00.00 - Transferências a Municípios - fundo a fundo
A32: 3.1.42.00.00 - Execução orçamentária delegada a Municípios
A33: 3.1.45.00.00 - Transferências fundo a fundo aos Municípios à conta de recursos de que tratam os §§ 1º e 2º do art. 24 da Lei Complementar nº 141, de 2012 - Restos a Pagar Cancelados
A34: 3.1.46.00.00 - Transferências fundo a fundo aos Municípios à conta de recursos de que trata o art. 25 da Lei Complementar nº 141, de 2012 - diferença do mínimo não aplicado em exercícios anteriores
... A45: 3.1.80.00.00 - Transferências ao Exterior
A46: 3.1.90.00.00 - Aplicações Diretas | B46: =+'DCA-Anexo I-D'!B47+'DCA-Anexo I-D'!B48+'DCA-Anexo I-D'!B49+'DCA-Anexo I-D'!B50+'DCA-Anexo I-D'!B51+'DCA-Anexo I-D'!B52+'DCA-Anexo I-D'!B53+'DCA-Anexo I-D'!B66+'DCA-Anexo I-D'!B67+'DCA-Anexo I-D'!B68+'DCA-Anexo I-D'!B69+'DCA-Anexo I-D'!B70+'DCA-Anexo I-D'!B71+'DCA-Anexo I-D'!B72+'DCA-Anexo I-D'!B73+'DCA-Anexo I-D'!B74+'DCA-Anexo I-D'!B54 -> 59121162 | C46: =+'DCA-Anexo I-D'!C47+'DCA-Anexo I-D'!C48+'DCA-Anexo I-D'!C49+'DCA-Anexo I-D'!C50+'DCA-Anexo I-D'!C51+'DCA-Anexo I-D'!C52+'DCA-Anexo I-D'!C53+'DCA-Anexo I-D'!C66+'DCA-Anexo I-D'!C67+'DCA-Anexo I-D'!C68+'DCA-Anexo I-D'!C69+'DCA-Anexo I-D'!C70+'DCA-Anexo I-D'!C71+'DCA-Anexo I-D'!C72+'DCA-Anexo I-D'!C73+'DCA-Anexo I-D'!C74+'DCA-Anexo I-D'!C54 -> 59121162 | D46: =+'DCA-Anexo I-D'!D47+'DCA-Anexo I-D'!D48+'DCA-Anexo I-D'!D49+'DCA-Anexo I-D'!D50+'DCA-Anexo I-D'!D51+'DCA-Anexo I-D'!D52+'DCA-Anexo I-D'!D53+'DCA-Anexo I-D'!D66+'DCA-Anexo I-D'!D67+'DCA-Anexo I-D'!D68+'DCA-Anexo I-D'!D69+'DCA-Anexo I-D'!D70+'DCA-Anexo I-D'!D71+'DCA-Anexo I-D'!D72+'DCA-Anexo I-D'!D73+'DCA-Anexo I-D'!D74+'DCA-Anexo I-D'!D54 -> 58738355 | E46: =+'DCA-Anexo I-D'!E47+'DCA-Anexo I-D'!E48+'DCA-Anexo I-D'!E49+'DCA-Anexo I-D'!E50+'DCA-Anexo I-D'!E51+'DCA-Anexo I-D'!E52+'DCA-Anexo I-D'!E53+'DCA-Anexo I-D'!E66+'DCA-Anexo I-D'!E67+'DCA-Anexo I-D'!E68+'DCA-Anexo I-D'!E69+'DCA-Anexo I-D'!E70+'DCA-Anexo I-D'!E71+'DCA-Anexo I-D'!E72+'DCA-Anexo I-D'!E73+'DCA-Anexo I-D'!E74+'DCA-Anexo I-D'!E54 -> 0 | F46: =+'DCA-Anexo I-D'!F47+'DCA-Anexo I-D'!F48+'DCA-Anexo I-D'!F49+'DCA-Anexo I-D'!F50+'DCA-Anexo I-D'!F51+'DCA-Anexo I-D'!F52+'DCA-Anexo I-D'!F53+'DCA-Anexo I-D'!F66+'DCA-Anexo I-D'!F67+'DCA-Anexo I-D'!F68+'DCA-Anexo I-D'!F69+'DCA-Anexo I-D'!F70+'DCA-Anexo I-D'!F71+'DCA-Anexo I-D'!F72+'DCA-Anexo I-D'!F73+'DCA-Anexo I-D'!F74+'DCA-Anexo I-D'!F54 -> 382806.31
A47: 3.1.90.01.00 - Aposentadorias do RPPS, Reserva Remunerada e Reformas dos Militares
A48: 3.1.90.03.00 - Pensões do RPPS e do Militar
A49: 3.1.90.04.00 - Contratação por Tempo Determinado | B49: 4552017.7 | C49: 4552017.7 | D49: 4552017.7
A50: 3.1.90.07.00 - Contribuição a Entidades Fechadas de Previdência
A51: 3.1.90.08.00 - Outros Benefícios Assistenciais do Servidor e do Militar
A52: 3.1.90.11.00 - Vencimentos e Vantagens Fixas - Pessoal Civil | B52: 48680902 | C52: 48680902 | D52: 48680902
A53: 3.1.90.12.00 - Vencimentos e Vantagens Fixas - Pessoal Militar
...

Sheet DCA-Anexo I-E
A2: QDCC
A3: BALANÇO ANUAL (DCA)
A4: VERSÃO: v14
A5: VIGÊNCIA: 05/01/2026
A7: Ente: 2908101 - Cocos/BA
A8: Poder: E - Executivo
A9: Instituição: 4063 - Prefeitura Municipal de Cocos - BA
A10: Exercício: 2025
A11: Periodicidade: ANUAL
A12: Período: Período único (anual)
A14: Grupo: Balanço Orçamentário - Despesas por Função
A15: Quadro: Despesas por Função
A16: Rótulo: Total Geral da Despesa por Função
A17: Despesas por Função | B17: Execução da Despesa
B18: Despesas Empenhadas | C18: Despesas Liquidadas | D18: Despesas Pagas | E18: Inscrição de Restos a Pagar Não Processados | F18: Inscrição de Restos a Pagar Processados
A19: Despesas Exceto Intraorçamentárias | B19: =+'DCA-Anexo I-E'!B20+'DCA-Anexo I-E'!B25+'DCA-Anexo I-E'!B30+'DCA-Anexo I-E'!B35+'DCA-Anexo I-E'!B48+'DCA-Anexo I-E'!B54+'DCA-Anexo I-E'!B60+'DCA-Anexo I-E'!B65+'DCA-Anexo I-E'!B74+'DCA-Anexo I-E'!B81+'DCA-Anexo I-E'!B90+'DCA-Anexo I-E'!B97+'DCA-Anexo I-E'!B108+'DCA-Anexo I-E'!B113+'DCA-Anexo I-E'!B119+'DCA-Anexo I-E'!B125+'DCA-Anexo I-E'!B130+'DCA-Anexo I-E'!B135+'DCA-Anexo I-E'!B143+'DCA-Anexo I-E'!B149+'DCA-Anexo I-E'!B157+'DCA-Anexo I-E'!B162+'DCA-Anexo I-E'!B170+'DCA-Anexo I-E'!B178+'DCA-Anexo I-E'!B183+'DCA-Anexo I-E'!B190+'DCA-Anexo I-E'!B198+'DCA-Anexo I-E'!B204 -> 1.4527209e+08 | C19: =+'DCA-Anexo I-E'!C20+'DCA-Anexo I-E'!C25+'DCA-Anexo I-E'!C30+'DCA-Anexo I-E'!C35+'DCA-Anexo I-E'!C48+'DCA-Anexo I-E'!C54+'DCA-Anexo I-E'!C60+'DCA-Anexo I-E'!C65+'DCA-Anexo I-E'!C74+'DCA-Anexo I-E'!C81+'DCA-Anexo I-E'!C90+'DCA-Anexo I-E'!C97+'DCA-Anexo I-E'!C108+'DCA-Anexo I-E'!C113+'DCA-Anexo I-E'!C119+'DCA-Anexo I-E'!C125+'DCA-Anexo I-E'!C130+'DCA-Anexo I-E'!C135+'DCA-Anexo I-E'!C143+'DCA-Anexo I-E'!C149+'DCA-Anexo I-E'!C157+'DCA-Anexo I-E'!C162+'DCA-Anexo I-E'!C170+'DCA-Anexo I-E'!C178+'DCA-Anexo I-E'!C183+'DCA-Anexo I-E'!C190+'DCA-Anexo I-E'!C198+'DCA-Anexo I-E'!C204 -> 1.4527209e+08 | D19: =+'DCA-Anexo I-E'!D20+'DCA-Anexo I-E'!D25+'DCA-Anexo I-E'!D30+'DCA-Anexo I-E'!D35+'DCA-Anexo I-E'!D48+'DCA-Anexo I-E'!D54+'DCA-Anexo I-E'!D60+'DCA-Anexo I-E'!D65+'DCA-Anexo I-E'!D74+'DCA-Anexo I-E'!D81+'DCA-Anexo I-E'!D90+'DCA-Anexo I-E'!D97+'DCA-Anexo I-E'!D108+'DCA-Anexo I-E'!D113+'DCA-Anexo I-E'!D119+'DCA-Anexo I-E'!D125+'DCA-Anexo I-E'!D130+'DCA-Anexo I-E'!D135+'DCA-Anexo I-E'!D143+'DCA-Anexo I-E'!D149+'DCA-Anexo I-E'!D157+'DCA-Anexo I-E'!D162+'DCA-Anexo I-E'!D170+'DCA-Anexo I-E'!D178+'DCA-Anexo I-E'!D183+'DCA-Anexo I-E'!D190+'DCA-Anexo I-E'!D198+'DCA-Anexo I-E'!D204 -> 1.3632376e+08 | E19: =+'DCA-Anexo I-E'!E20+'DCA-Anexo I-E'!E25+'DCA-Anexo I-E'!E30+'DCA-Anexo I-E'!E35+'DCA-Anexo I-E'!E48+'DCA-Anexo I-E'!E54+'DCA-Anexo I-E'!E60+'DCA-Anexo I-E'!E65+'DCA-Anexo I-E'!E74+'DCA-Anexo I-E'!E81+'DCA-Anexo I-E'!E90+'DCA-Anexo I-E'!E97+'DCA-Anexo I-E'!E108+'DCA-Anexo I-E'!E113+'DCA-Anexo I-E'!E119+'DCA-Anexo I-E'!E125+'DCA-Anexo I-E'!E130+'DCA-Anexo I-E'!E135+'DCA-Anexo I-E'!E143+'DCA-Anexo I-E'!E149+'DCA-Anexo I-E'!E157+'DCA-Anexo I-E'!E162+'DCA-Anexo I-E'!E170+'DCA-Anexo I-E'!E178+'DCA-Anexo I-E'!E183+'DCA-Anexo I-E'!E190+'DCA-Anexo I-E'!E198+'DCA-Anexo I-E'!E204 -> 0 | F19: =+'DCA-Anexo I-E'!F20+'DCA-Anexo I-E'!F25+'DCA-Anexo I-E'!F30+'DCA-Anexo I-E'!F35+'DCA-Anexo I-E'!F48+'DCA-Anexo I-E'!F54+'DCA-Anexo I-E'!F60+'DCA-Anexo I-E'!F65+'DCA-Anexo I-E'!F74+'DCA-Anexo I-E'!F81+'DCA-Anexo I-E'!F90+'DCA-Anexo I-E'!F97+'DCA-Anexo I-E'!F108+'DCA-Anexo I-E'!F113+'DCA-Anexo I-E'!F119+'DCA-Anexo I-E'!F125+'DCA-Anexo I-E'!F130+'DCA-Anexo I-E'!F135+'DCA-Anexo I-E'!F143+'DCA-Anexo I-E'!F149+'DCA-Anexo I-E'!F157+'DCA-Anexo I-E'!F162+'DCA-Anexo I-E'!F170+'DCA-Anexo I-E'!F178+'DCA-Anexo I-E'!F183+'DCA-Anexo I-E'!F190+'DCA-Anexo I-E'!F198+'DCA-Anexo I-E'!F204 -> 8948337.3
A20: 01 - Legislativa | B20: =+'DCA-Anexo I-E'!B21+'DCA-Anexo I-E'!B22+'DCA-Anexo I-E'!B24+'DCA-Anexo I-E'!B23 -> 4989007.9 | C20: =+'DCA-Anexo I-E'!C21+'DCA-Anexo I-E'!C22+'DCA-Anexo I-E'!C24+'DCA-Anexo I-E'!C23 -> 4989007.9 | D20: =+'DCA-Anexo I-E'!D21+'DCA-Anexo I-E'!D22+'DCA-Anexo I-E'!D24+'DCA-Anexo I-E'!D23 -> 4989007.9 | E20: =+'DCA-Anexo I-E'!E21+'DCA-Anexo I-E'!E22+'DCA-Anexo I-E'!E24+'DCA-Anexo I-E'!E23 -> 0 | F20: =+'DCA-Anexo I-E'!F21+'DCA-Anexo I-E'!F22+'DCA-Anexo I-E'!F24+'DCA-Anexo I-E'!F23 -> 0
A21: 01.031 - Ação Legislativa | B21: 4989007.9 | C21: 4989007.9 | D21: 4989007.9
A22: 01.032 - Controle Externo
A23: 01.122 - Administração Geral
A24: FU01 - Demais Subfunções
A25: 02 - Judiciária | B25: =+'DCA-Anexo I-E'!B26+'DCA-Anexo I-E'!B27+'DCA-Anexo I-E'!B29+'DCA-Anexo I-E'!B28 -> 460995.4 | C25: =+'DCA-Anexo I-E'!C26+'DCA-Anexo I-E'!C27+'DCA-Anexo I-E'!C29+'DCA-Anexo I-E'!C28 -> 460995.4 | D25: =+'DCA-Anexo I-E'!D26+'DCA-Anexo I-E'!D27+'DCA-Anexo I-E'!D29+'DCA-Anexo I-E'!D28 -> 358595.4 | E25: =+'DCA-Anexo I-E'!E26+'DCA-Anexo I-E'!E27+'DCA-Anexo I-E'!E29+'DCA-Anexo I-E'!E28 -> 0 | F25: =+'DCA-Anexo I-E'!F26+'DCA-Anexo I-E'!F27+'DCA-Anexo I-E'!F29+'DCA-Anexo I-E'!F28 -> 102400
A26: 02.061 - Ação Judiciária | B26: 460995.4 | C26: 460995.4 | D26: 358595.4 | F26: 102400
A27: 02.062 - Defesa do Interesse Público no Processo Judiciário
A28: 02.122 - Administração Geral
A29: FU02 - Demais Subfunções
A30: 03 - Essencial à Justiça | B30: =+'DCA-Anexo I-E'!B31+'DCA-Anexo I-E'!B32+'DCA-Anexo I-E'!B34+'DCA-Anexo I-E'!B33 -> 0 | C30: =+'DCA-Anexo I-E'!C31+'DCA-Anexo I-E'!C32+'DCA-Anexo I-E'!C34+'DCA-Anexo I-E'!C33 -> 0 | D30: =+'DCA-Anexo I-E'!D31+'DCA-Anexo I-E'!D32+'DCA-Anexo I-E'!D34+'DCA-Anexo I-E'!D33 -> 0 | E30: =+'DCA-Anexo I-E'!E31+'DCA-Anexo I-E'!E32+'DCA-Anexo I-E'!E34+'DCA-Anexo I-E'!E33 -> 0 | F30: =+'DCA-Anexo I-E'!F31+'DCA-Anexo I-E'!F32+'DCA-Anexo I-E'!F34+'DCA-Anexo I-E'!F33 -> 0
A31: 03.091 - Defesa da Ordem Jurídica
A32: 03.092 - Representação Judicial e Extrajudicial
A33: 03.122 - Administração Geral
A34: FU03 - Demais Subfunções
A35: 04 - Administração | B35: =+'DCA-Anexo I-E'!B36+'DCA-Anexo I-E'!B37+'DCA-Anexo I-E'!B38+'DCA-Anexo I-E'!B39+'DCA-Anexo I-E'!B40+'DCA-Anexo I-E'!B41+'DCA-Anexo I-E'!B42+'DCA-Anexo I-E'!B43+'DCA-Anexo I-E'!B44+'DCA-Anexo I-E'!B45+'DCA-Anexo I-E'!B46+'DCA-Anexo I-E'!B47 -> 12767311 | C35: =+'DCA-Anexo I-E'!C36+'DCA-Anexo I-E'!C37+'DCA-Anexo I-E'!C38+'DCA-Anexo I-E'!C39+'DCA-Anexo I-E'!C40+'DCA-Anexo I-E'!C41+'DCA-Anexo I-E'!C42+'DCA-Anexo I-E'!C43+'DCA-Anexo I-E'!C44+'DCA-Anexo I-E'!C45+'DCA-Anexo I-E'!C46+'DCA-Anexo I-E'!C47 -> 12767311 | D35: =+'DCA-Anexo I-E'!D36+'DCA-Anexo I-E'!D37+'DCA-Anexo I-E'!D38+'DCA-Anexo I-E'!D39+'DCA-Anexo I-E'!D40+'DCA-Anexo I-E'!D41+'DCA-Anexo I-E'!D42+'DCA-Anexo I-E'!D43+'DCA-Anexo I-E'!D44+'DCA-Anexo I-E'!D45+'DCA-Anexo I-E'!D46+'DCA-Anexo I-E'!D47 -> 12360224 | E35: =+'DCA-Anexo I-E'!E36+'DCA-Anexo I-E'!E37+'DCA-Anexo I-E'!E38+'DCA-Anexo I-E'!E39+'DCA-Anexo I-E'!E40+'DCA-Anexo I-E'!E41+'DCA-Anexo I-E'!E42+'DCA-Anexo I-E'!E43+'DCA-Anexo I-E'!E44+'DCA-Anexo I-E'!E45+'DCA-Anexo I-E'!E46+'DCA-Anexo I-E'!E47 -> 0 | F35: =+'DCA-Anexo I-E'!F36+'DCA-Anexo I-E'!F37+'DCA-Anexo I-E'!F38+'DCA-Anexo I-E'!F39+'DCA-Anexo I-E'!F40+'DCA-Anexo I-E'!F41+'DCA-Anexo I-E'!F42+'DCA-Anexo I-E'!F43+'DCA-Anexo I-E'!F44+'DCA-Anexo I-E'!F45+'DCA-Anexo I-E'!F46+'DCA-Anexo I-E'!F47 -> 407086.53
A36: 04.121 - Planejamento e Orçamento
A37: 04.122 - Administração Geral | B37: 11177423 | C37: 11177423 | D37: 10842416 | F37: 335007.53
A38: 04.123 - Administração Financeira | B38: 1589887.7 | C38: 1589887.7 | D38: 1517808.7 | F38: 72079
A39: 04.124 - Controle Interno
A40: 04.125 - Normatização e Fiscalização
A41: 04.126 - Tecnologia da Informação
A42: 04.127 - Ordenamento Territorial
A43: 04.128 - Formação de Recursos Humanos
...

Sheet DCA-Anexo I-F
A2: QDCC
A3: BALANÇO ANUAL (DCA)
A4: VERSÃO: v14
A5: VIGÊNCIA: 05/01/2026
A7: Ente: 2908101 - Cocos/BA
A8: Poder: E - Executivo
A9: Instituição: 4063 - Prefeitura Municipal de Cocos - BA
A10: Exercício: 2025
A11: Periodicidade: ANUAL
A12: Período: Período único (anual)
A14: Grupo: Balanço Orçamentário - Despesas Orçamentárias - Sub Quadro - Execução dos Restos a Pagar
A15: Quadro: Despesas Orçamentárias
A16: Rótulo: Padrão
A17: Despesas Orçamentárias | B17: Execução da Despesa
B18: Restos a Pagar Não Processados Inscritos em Exercícios Anteriores | C18: Restos a Pagar Não Processados Inscritos em 31 de Dezembro do Exercício Anterior | D18: Restos a Pagar Não Processados Liquidados | E18: Restos a Pagar Não Processados Pagos | F18: Restos a Pagar Não Processados Cancelados | G18: Restos a Pagar Processados Inscritos em Exercícios Anteriores | H18: Restos a Pagar Processados Inscritos em 31 de Dezembro do Exercício Anterior | I18: Restos a Pagar Processados Pagos | J18: Restos a Pagar Processados Cancelados
A19: Despesas Orçamentárias
A20: Total Despesas | B20: =+'DCA-Anexo I-F'!B21+'DCA-Anexo I-F'!B235 -> 62175.76 | C20: =+'DCA-Anexo I-F'!C21+'DCA-Anexo I-F'!C235 -> 20650.4 | D20: =+'DCA-Anexo I-F'!D21+'DCA-Anexo I-F'!D235 -> 20650.4 | E20: =+'DCA-Anexo I-F'!E21+'DCA-Anexo I-F'!E235 -> 20650.4 | F20: =+'DCA-Anexo I-F'!F21+'DCA-Anexo I-F'!F235 -> 0 | G20: =+'DCA-Anexo I-F'!G21+'DCA-Anexo I-F'!G235 -> 678963.1 | H20: =+'DCA-Anexo I-F'!H21+'DCA-Anexo I-F'!H235 -> 513963.84 | I20: =+'DCA-Anexo I-F'!I21+'DCA-Anexo I-F'!I235 -> 511422.29 | J20: =+'DCA-Anexo I-F'!J21+'DCA-Anexo I-F'!J235 -> 0
A21: 3.0.00.00.00 - Despesas Correntes | B21: =+'DCA-Anexo I-F'!B22+'DCA-Anexo I-F'!B145+'DCA-Anexo I-F'!B103 -> 54275.76 | C21: =+'DCA-Anexo I-F'!C22+'DCA-Anexo I-F'!C145+'DCA-Anexo I-F'!C103 -> 20650.4 | D21: =+'DCA-Anexo I-F'!D22+'DCA-Anexo I-F'!D145+'DCA-Anexo I-F'!D103 -> 20650.4 | E21: =+'DCA-Anexo I-F'!E22+'DCA-Anexo I-F'!E145+'DCA-Anexo I-F'!E103 -> 20650.4 | F21: =+'DCA-Anexo I-F'!F22+'DCA-Anexo I-F'!F145+'DCA-Anexo I-F'!F103 -> 0 | G21: =+'DCA-Anexo I-F'!G22+'DCA-Anexo I-F'!G145+'DCA-Anexo I-F'!G103 -> 636396.89 | H21: =+'DCA-Anexo I-F'!H22+'DCA-Anexo I-F'!H145+'DCA-Anexo I-F'!H103 -> 331717.09 | I21: =+'DCA-Anexo I-F'!I22+'DCA-Anexo I-F'!I145+'DCA-Anexo I-F'!I103 -> 329175.54 | J21: =+'DCA-Anexo I-F'!J22+'DCA-Anexo I-F'!J145+'DCA-Anexo I-F'!J103 -> 0
A22: 3.1.00.00.00 - Pessoal e Encargos Sociais | B22: =+'DCA-Anexo I-F'!B101+'DCA-Anexo I-F'!B30+'DCA-Anexo I-F'!B39+'DCA-Anexo I-F'!B75+'DCA-Anexo I-F'!B26+'DCA-Anexo I-F'!B34+'DCA-Anexo I-F'!B102+'DCA-Anexo I-F'!B44+'DCA-Anexo I-F'!B24+'DCA-Anexo I-F'!B29+'DCA-Anexo I-F'!B25+'DCA-Anexo I-F'!B37+'DCA-Anexo I-F'!B28+'DCA-Anexo I-F'!B27+'DCA-Anexo I-F'!B42+'DCA-Anexo I-F'!B43+'DCA-Anexo I-F'!B99+'DCA-Anexo I-F'!B46+'DCA-Anexo I-F'!B32+'DCA-Anexo I-F'!B100+'DCA-Anexo I-F'!B35+'DCA-Anexo I-F'!B23+'DCA-Anexo I-F'!B41+'DCA-Anexo I-F'!B38+'DCA-Anexo I-F'!B98+'DCA-Anexo I-F'!B31+'DCA-Anexo I-F'!B33+'DCA-Anexo I-F'!B36+'DCA-Anexo I-F'!B45+'DCA-Anexo I-F'!B40+'DCA-Anexo I-F'!B97 -> 0 | C22: =+'DCA-Anexo I-F'!C101+'DCA-Anexo I-F'!C30+'DCA-Anexo I-F'!C39+'DCA-Anexo I-F'!C75+'DCA-Anexo I-F'!C26+'DCA-Anexo I-F'!C34+'DCA-Anexo I-F'!C102+'DCA-Anexo I-F'!C44+'DCA-Anexo I-F'!C24+'DCA-Anexo I-F'!C29+'DCA-Anexo I-F'!C25+'DCA-Anexo I-F'!C37+'DCA-Anexo I-F'!C28+'DCA-Anexo I-F'!C27+'DCA-Anexo I-F'!C42+'DCA-Anexo I-F'!C43+'DCA-Anexo I-F'!C99+'DCA-Anexo I-F'!C46+'DCA-Anexo I-F'!C32+'DCA-Anexo I-F'!C100+'DCA-Anexo I-F'!C35+'DCA-Anexo I-F'!C23+'DCA-Anexo I-F'!C41+'DCA-Anexo I-F'!C38+'DCA-Anexo I-F'!C98+'DCA-Anexo I-F'!C31+'DCA-Anexo I-F'!C33+'DCA-Anexo I-F'!C36+'DCA-Anexo I-F'!C45+'DCA-Anexo I-F'!C40+'DCA-Anexo I-F'!C97 -> 0 | D22: =+'DCA-Anexo I-F'!D101+'DCA-Anexo I-F'!D30+'DCA-Anexo I-F'!D39+'DCA-Anexo I-F'!D75+'DCA-Anexo I-F'!D26+'DCA-Anexo I-F'!D34+'DCA-Anexo I-F'!D102+'DCA-Anexo I-F'!D44+'DCA-Anexo I-F'!D24+'DCA-Anexo I-F'!D29+'DCA-Anexo I-F'!D25+'DCA-Anexo I-F'!D37+'DCA-Anexo I-F'!D28+'DCA-Anexo I-F'!D27+'DCA-Anexo I-F'!D42+'DCA-Anexo I-F'!D43+'DCA-Anexo I-F'!D99+'DCA-Anexo I-F'!D46+'DCA-Anexo I-F'!D32+'DCA-Anexo I-F'!D100+'DCA-Anexo I-F'!D35+'DCA-Anexo I-F'!D23+'DCA-Anexo I-F'!D41+'DCA-Anexo I-F'!D38+'DCA-Anexo I-F'!D98+'DCA-Anexo I-F'!D31+'DCA-Anexo I-F'!D33+'DCA-Anexo I-F'!D36+'DCA-Anexo I-F'!D45+'DCA-Anexo I-F'!D40+'DCA-Anexo I-F'!D97 -> 0 | E22: =+'DCA-Anexo I-F'!E101+'DCA-Anexo I-F'!E30+'DCA-Anexo I-F'!E39+'DCA-Anexo I-F'!E75+'DCA-Anexo I-F'!E26+'DCA-Anexo I-F'!E34+'DCA-Anexo I-F'!E102+'DCA-Anexo I-F'!E44+'DCA-Anexo I-F'!E24+'DCA-Anexo I-F'!E29+'DCA-Anexo I-F'!E25+'DCA-Anexo I-F'!E37+'DCA-Anexo I-F'!E28+'DCA-Anexo I-F'!E27+'DCA-Anexo I-F'!E42+'DCA-Anexo I-F'!E43+'DCA-Anexo I-F'!E99+'DCA-Anexo I-F'!E46+'DCA-Anexo I-F'!E32+'DCA-Anexo I-F'!E100+'DCA-Anexo I-F'!E35+'DCA-Anexo I-F'!E23+'DCA-Anexo I-F'!E41+'DCA-Anexo I-F'!E38+'DCA-Anexo I-F'!E98+'DCA-Anexo I-F'!E31+'DCA-Anexo I-F'!E33+'DCA-Anexo I-F'!E36+'DCA-Anexo I-F'!E45+'DCA-Anexo I-F'!E40+'DCA-Anexo I-F'!E97 -> 0 | F22: =+'DCA-Anexo I-F'!F101+'DCA-Anexo I-F'!F30+'DCA-Anexo I-F'!F39+'DCA-Anexo I-F'!F75+'DCA-Anexo I-F'!F26+'DCA-Anexo I-F'!F34+'DCA-Anexo I-F'!F102+'DCA-Anexo I-F'!F44+'DCA-Anexo I-F'!F24+'DCA-Anexo I-F'!F29+'DCA-Anexo I-F'!F25+'DCA-Anexo I-F'!F37+'DCA-Anexo I-F'!F28+'DCA-Anexo I-F'!F27+'DCA-Anexo I-F'!F42+'DCA-Anexo I-F'!F43+'DCA-Anexo I-F'!F99+'DCA-Anexo I-F'!F46+'DCA-Anexo I-F'!F32+'DCA-Anexo I-F'!F100+'DCA-Anexo I-F'!F35+'DCA-Anexo I-F'!F23+'DCA-Anexo I-F'!F41+'DCA-Anexo I-F'!F38+'DCA-Anexo I-F'!F98+'DCA-Anexo I-F'!F31+'DCA-Anexo I-F'!F33+'DCA-Anexo I-F'!F36+'DCA-Anexo I-F'!F45+'DCA-Anexo I-F'!F40+'DCA-Anexo I-F'!F97 -> 0 | G22: =+'DCA-Anexo I-F'!G101+'DCA-Anexo I-F'!G30+'DCA-Anexo I-F'!G39+'DCA-Anexo I-F'!G75+'DCA-Anexo I-F'!G26+'DCA-Anexo I-F'!G34+'DCA-Anexo I-F'!G102+'DCA-Anexo I-F'!G44+'DCA-Anexo I-F'!G24+'DCA-Anexo I-F'!G29+'DCA-Anexo I-F'!G25+'DCA-Anexo I-F'!G37+'DCA-Anexo I-F'!G28+'DCA-Anexo I-F'!G27+'DCA-Anexo I-F'!G42+'DCA-Anexo I-F'!G43+'DCA-Anexo I-F'!G99+'DCA-Anexo I-F'!G46+'DCA-Anexo I-F'!G32+'DCA-Anexo I-F'!G100+'DCA-Anexo I-F'!G35+'DCA-Anexo I-F'!G23+'DCA-Anexo I-F'!G41+'DCA-Anexo I-F'!G38+'DCA-Anexo I-F'!G98+'DCA-Anexo I-F'!G31+'DCA-Anexo I-F'!G33+'DCA-Anexo I-F'!G36+'DCA-Anexo I-F'!G45+'DCA-Anexo I-F'!G40+'DCA-Anexo I-F'!G97 -> 7130.4 | H22: =+'DCA-Anexo I-F'!H101+'DCA-Anexo I-F'!H30+'DCA-Anexo I-F'!H39+'DCA-Anexo I-F'!H75+'DCA-Anexo I-F'!H26+'DCA-Anexo I-F'!H34+'DCA-Anexo I-F'!H102+'DCA-Anexo I-F'!H44+'DCA-Anexo I-F'!H24+'DCA-Anexo I-F'!H29+'DCA-Anexo I-F'!H25+'DCA-Anexo I-F'!H37+'DCA-Anexo I-F'!H28+'DCA-Anexo I-F'!H27+'DCA-Anexo I-F'!H42+'DCA-Anexo I-F'!H43+'DCA-Anexo I-F'!H99+'DCA-Anexo I-F'!H46+'DCA-Anexo I-F'!H32+'DCA-Anexo I-F'!H100+'DCA-Anexo I-F'!H35+'DCA-Anexo I-F'!H23+'DCA-Anexo I-F'!H41+'DCA-Anexo I-F'!H38+'DCA-Anexo I-F'!H98+'DCA-Anexo I-F'!H31+'DCA-Anexo I-F'!H33+'DCA-Anexo I-F'!H36+'DCA-Anexo I-F'!H45+'DCA-Anexo I-F'!H40+'DCA-Anexo I-F'!H97 -> 75981.93 | I22: =+'DCA-Anexo I-F'!I101+'DCA-Anexo I-F'!I30+'DCA-Anexo I-F'!I39+'DCA-Anexo I-F'!I75+'DCA-Anexo I-F'!I26+'DCA-Anexo I-F'!I34+'DCA-Anexo I-F'!I102+'DCA-Anexo I-F'!I44+'DCA-Anexo I-F'!I24+'DCA-Anexo I-F'!I29+'DCA-Anexo I-F'!I25+'DCA-Anexo I-F'!I37+'DCA-Anexo I-F'!I28+'DCA-Anexo I-F'!I27+'DCA-Anexo I-F'!I42+'DCA-Anexo I-F'!I43+'DCA-Anexo I-F'!I99+'DCA-Anexo I-F'!I46+'DCA-Anexo I-F'!I32+'DCA-Anexo I-F'!I100+'DCA-Anexo I-F'!I35+'DCA-Anexo I-F'!I23+'DCA-Anexo I-F'!I41+'DCA-Anexo I-F'!I38+'DCA-Anexo I-F'!I98+'DCA-Anexo I-F'!I31+'DCA-Anexo I-F'!I33+'DCA-Anexo I-F'!I36+'DCA-Anexo I-F'!I45+'DCA-Anexo I-F'!I40+'DCA-Anexo I-F'!I97 -> 75981.93 | J22: =+'DCA-Anexo I-F'!J101+'DCA-Anexo I-F'!J30+'DCA-Anexo I-F'!J39+'DCA-Anexo I-F'!J75+'DCA-Anexo I-F'!J26+'DCA-Anexo I-F'!J34+'DCA-Anexo I-F'!J102+'DCA-Anexo I-F'!J44+'DCA-Anexo I-F'!J24+'DCA-Anexo I-F'!J29+'DCA-Anexo I-F'!J25+'DCA-Anexo I-F'!J37+'DCA-Anexo I-F'!J28+'DCA-Anexo I-F'!J27+'DCA-Anexo I-F'!J42+'DCA-Anexo I-F'!J43+'DCA-Anexo I-F'!J99+'DCA-Anexo I-F'!J46+'DCA-Anexo I-F'!J32+'DCA-Anexo I-F'!J100+'DCA-Anexo I-F'!J35+'DCA-Anexo I-F'!J23+'DCA-Anexo I-F'!J41+'DCA-Anexo I-F'!J38+'DCA-Anexo I-F'!J98+'DCA-Anexo I-F'!J31+'DCA-Anexo I-F'!J33+'DCA-Anexo I-F'!J36+'DCA-Anexo I-F'!J45+'DCA-Anexo I-F'!J40+'DCA-Anexo I-F'!J97 -> 0
A23: 3.1.20.00.00 - Transferências à União
A24: 3.1.22.00.00 - Execução orçamentária delegada à União
A25: 3.1.30.00.00 - Transferências a Estados e ao Distrito Federal
A26: 3.1.31.00.00 - Transferências a Estados e ao Distrito Federal - fundo a fundo
A27: 3.1.32.00.00 - Execução orçamentária delegada a Estados e ao Distrito Federal
A28: 3.1.35.00.00 - Transferências fundo a fundo aos Estados e ao Distrito Federal à conta de recursos de que tratam os §§ 1º e 2º do art. 24 da Lei Complementar nº 141, de 2012 - Restos a Pagar Cancelados
A29: 3.1.36.00.00 - Transferências fundo a fundo aos Estados e ao Distrito Federal à conta de recursos de que trata o art. 25 da Lei Complementar nº 141, de 2012 - diferença do mínimo não aplicado em exercícios anteriores
A30: 3.1.40.00.00 - Transferências a Municípios
A31: 3.1.41.00.00 - Transferências a Municípios - fundo a fundo
A32: 3.1.42.00.00 - Execução orçamentária delegada a Municípios
A33: 3.1.45.00.00 - Transferências fundo a fundo aos Municípios à conta de recursos de que tratam os §§ 1º e 2º do art. 24 da Lei Complementar nº 141, de 2012 - Restos a Pagar Cancelados
A34: 3.1.46.00.00 - Transferências fundo a fundo aos Municípios à conta de recursos de que trata o art. 25 da Lei Complementar nº 141, de 2012 - diferença do mínimo não aplicado em exercícios anteriores
... A45: 3.1.80.00.00 - Transferências ao Exterior
A46: 3.1.90.00.00 - Aplicações Diretas | B46: =+'DCA-Anexo I-F'!B47+'DCA-Anexo I-F'!B48+'DCA-Anexo I-F'!B49+'DCA-Anexo I-F'!B50+'DCA-Anexo I-F'!B51+'DCA-Anexo I-F'!B52+'DCA-Anexo I-F'!B53+'DCA-Anexo I-F'!B66+'DCA-Anexo I-F'!B67+'DCA-Anexo I-F'!B68+'DCA-Anexo I-F'!B69+'DCA-Anexo I-F'!B70+'DCA-Anexo I-F'!B71+'DCA-Anexo I-F'!B72+'DCA-Anexo I-F'!B73+'DCA-Anexo I-F'!B74+'DCA-Anexo I-F'!B54 -> 0 | C46: =+'DCA-Anexo I-F'!C47+'DCA-Anexo I-F'!C48+'DCA-Anexo I-F'!C49+'DCA-Anexo I-F'!C50+'DCA-Anexo I-F'!C51+'DCA-Anexo I-F'!C52+'DCA-Anexo I-F'!C53+'DCA-Anexo I-F'!C66+'DCA-Anexo I-F'!C67+'DCA-Anexo I-F'!C68+'DCA-Anexo I-F'!C69+'DCA-Anexo I-F'!C70+'DCA-Anexo I-F'!C71+'DCA-Anexo I-F'!C72+'DCA-Anexo I-F'!C73+'DCA-Anexo I-F'!C74+'DCA-Anexo I-F'!C54 -> 0 | D46: =+'DCA-Anexo I-F'!D47+'DCA-Anexo I-F'!D48+'DCA-Anexo I-F'!D49+'DCA-Anexo I-F'!D50+'DCA-Anexo I-F'!D51+'DCA-Anexo I-F'!D52+'DCA-Anexo I-F'!D53+'DCA-Anexo I-F'!D66+'DCA-Anexo I-F'!D67+'DCA-Anexo I-F'!D68+'DCA-Anexo I-F'!D69+'DCA-Anexo I-F'!D70+'DCA-Anexo I-F'!D71+'DCA-Anexo I-F'!D72+'DCA-Anexo I-F'!D73+'DCA-Anexo I-F'!D74+'DCA-Anexo I-F'!D54 -> 0 | E46: =+'DCA-Anexo I-F'!E47+'DCA-Anexo I-F'!E48+'DCA-Anexo I-F'!E49+'DCA-Anexo I-F'!E50+'DCA-Anexo I-F'!E51+'DCA-Anexo I-F'!E52+'DCA-Anexo I-F'!E53+'DCA-Anexo I-F'!E66+'DCA-Anexo I-F'!E67+'DCA-Anexo I-F'!E68+'DCA-Anexo I-F'!E69+'DCA-Anexo I-F'!E70+'DCA-Anexo I-F'!E71+'DCA-Anexo I-F'!E72+'DCA-Anexo I-F'!E73+'DCA-Anexo I-F'!E74+'DCA-Anexo I-F'!E54 -> 0 | F46: =+'DCA-Anexo I-F'!F47+'DCA-Anexo I-F'!F48+'DCA-Anexo I-F'!F49+'DCA-Anexo I-F'!F50+'DCA-Anexo I-F'!F51+'DCA-Anexo I-F'!F52+'DCA-Anexo I-F'!F53+'DCA-Anexo I-F'!F66+'DCA-Anexo I-F'!F67+'DCA-Anexo I-F'!F68+'DCA-Anexo I-F'!F69+'DCA-Anexo I-F'!F70+'DCA-Anexo I-F'!F71+'DCA-Anexo I-F'!F72+'DCA-Anexo I-F'!F73+'DCA-Anexo I-F'!F74+'DCA-Anexo I-F'!F54 -> 0 | G46: =+'DCA-Anexo I-F'!G47+'DCA-Anexo I-F'!G48+'DCA-Anexo I-F'!G49+'DCA-Anexo I-F'!G50+'DCA-Anexo I-F'!G51+'DCA-Anexo I-F'!G52+'DCA-Anexo I-F'!G53+'DCA-Anexo I-F'!G66+'DCA-Anexo I-F'!G67+'DCA-Anexo I-F'!G68+'DCA-Anexo I-F'!G69+'DCA-Anexo I-F'!G70+'DCA-Anexo I-F'!G71+'DCA-Anexo I-F'!G72+'DCA-Anexo I-F'!G73+'DCA-Anexo I-F'!G74+'DCA-Anexo I-F'!G54 -> 7130.4 | H46: =+'DCA-Anexo I-F'!H47+'DCA-Anexo I-F'!H48+'DCA-Anexo I-F'!H49+'DCA-Anexo I-F'!H50+'DCA-Anexo I-F'!H51+'DCA-Anexo I-F'!H52+'DCA-Anexo I-F'!H53+'DCA-Anexo I-F'!H66+'DCA-Anexo I-F'!H67+'DCA-Anexo I-F'!H68+'DCA-Anexo I-F'!H69+'DCA-Anexo I-F'!H70+'DCA-Anexo I-F'!H71+'DCA-Anexo I-F'!H72+'DCA-Anexo I-F'!H73+'DCA-Anexo I-F'!H74+'DCA-Anexo I-F'!H54 -> 75981.93 | I46: =+'DCA-Anexo I-F'!I47+'DCA-Anexo I-F'!I48+'DCA-Anexo I-F'!I49+'DCA-Anexo I-F'!I50+'DCA-Anexo I-F'!I51+'DCA-Anexo I-F'!I52+'DCA-Anexo I-F'!I53+'DCA-Anexo I-F'!I66+'DCA-Anexo I-F'!I67+'DCA-Anexo I-F'!I68+'DCA-Anexo I-F'!I69+'DCA-Anexo I-F'!I70+'DCA-Anexo I-F'!I71+'DCA-Anexo I-F'!I72+'DCA-Anexo I-F'!I73+'DCA-Anexo I-F'!I74+'DCA-Anexo I-F'!I54 -> 75981.93 | J46: =+'DCA-Anexo I-F'!J47+'DCA-Anexo I-F'!J48+'DCA-Anexo I-F'!J49+'DCA-Anexo I-F'!J50+'DCA-Anexo I-F'!J51+'DCA-Anexo I-F'!J52+'DCA-Anexo I-F'!J53+'DCA-Anexo I-F'!J66+'DCA-Anexo I-F'!J67+'DCA-Anexo I-F'!J68+'DCA-Anexo I-F'!J69+'DCA-Anexo I-F'!J70+'DCA-Anexo I-F'!J71+'DCA-Anexo I-F'!J72+'DCA-Anexo I-F'!J73+'DCA-Anexo I-F'!J74+'DCA-Anexo I-F'!J54 -> 0
A47: 3.1.90.01.00 - Aposentadorias do RPPS, Reserva Remunerada e Reformas dos Militares
A48: 3.1.90.03.00 - Pensões do RPPS e do Militar
A49: 3.1.90.04.00 - Contratação por Tempo Determinado | G49: 7130.4
A50: 3.1.90.07.00 - Contribuição a Entidades Fechadas de Previdência
A51: 3.1.90.08.00 - Outros Benefícios Assistenciais do Servidor e do Militar
A52: 3.1.90.11.00 - Vencimentos e Vantagens Fixas - Pessoal Civil | F52: 0 | H52: 75981.93 | I52: 75981.93
A53: 3.1.90.12.00 - Vencimentos e Vantagens Fixas - Pessoal Militar
...

Sheet DCA-Anexo I-G
A2: QDCC
A3: BALANÇO ANUAL (DCA)
A4: VERSÃO: v14
A5: VIGÊNCIA: 05/01/2026
A7: Ente: 2908101 - Cocos/BA
A8: Poder: E - Executivo
A9: Instituição: 4063 - Prefeitura Municipal de Cocos - BA
A10: Exercício: 2025
A11: Periodicidade: ANUAL
A12: Período: Período único (anual)
A14: Grupo: Balanço Orçamentário - Despesas por Função - Sub Quadro - Execução dos Restos a Pagar
A15: Quadro: Despesas por Função
A16: Rótulo: Total Geral da Despesa por Função
A17: Despesas por Função | B17: Execução da Despesa
B18: Restos a Pagar Não Processados Inscritos em Exercícios Anteriores | C18: Restos a Pagar Não Processados Inscritos em 31 de Dezembro do Exercício Anterior | D18: Restos a Pagar Não Processados Liquidados | E18: Restos a Pagar Não Processados Pagos | F18: Restos a Pagar Não Processados Cancelados | G18: Restos a Pagar Processados Inscritos em Exercícios Anteriores | H18: Restos a Pagar Processados Inscritos em 31 de Dezembro do Exercício Anterior | I18: Restos a Pagar Processados Pagos | J18: Restos a Pagar Processados Cancelados
A19: Despesas Exceto Intraorçamentárias | B19: =+'DCA-Anexo I-G'!B20+'DCA-Anexo I-G'!B25+'DCA-Anexo I-G'!B30+'DCA-Anexo I-G'!B35+'DCA-Anexo I-G'!B48+'DCA-Anexo I-G'!B54+'DCA-Anexo I-G'!B60+'DCA-Anexo I-G'!B65+'DCA-Anexo I-G'!B74+'DCA-Anexo I-G'!B81+'DCA-Anexo I-G'!B90+'DCA-Anexo I-G'!B97+'DCA-Anexo I-G'!B108+'DCA-Anexo I-G'!B113+'DCA-Anexo I-G'!B119+'DCA-Anexo I-G'!B125+'DCA-Anexo I-G'!B130+'DCA-Anexo I-G'!B135+'DCA-Anexo I-G'!B143+'DCA-Anexo I-G'!B149+'DCA-Anexo I-G'!B157+'DCA-Anexo I-G'!B162+'DCA-Anexo I-G'!B170+'DCA-Anexo I-G'!B178+'DCA-Anexo I-G'!B183+'DCA-Anexo I-G'!B190+'DCA-Anexo I-G'!B198+'DCA-Anexo I-G'!B204 -> 62175.76 | C19: =+'DCA-Anexo I-G'!C20+'DCA-Anexo I-G'!C25+'DCA-Anexo I-G'!C30+'DCA-Anexo I-G'!C35+'DCA-Anexo I-G'!C48+'DCA-Anexo I-G'!C54+'DCA-Anexo I-G'!C60+'DCA-Anexo I-G'!C65+'DCA-Anexo I-G'!C74+'DCA-Anexo I-G'!C81+'DCA-Anexo I-G'!C90+'DCA-Anexo I-G'!C97+'DCA-Anexo I-G'!C108+'DCA-Anexo I-G'!C113+'DCA-Anexo I-G'!C119+'DCA-Anexo I-G'!C125+'DCA-Anexo I-G'!C130+'DCA-Anexo I-G'!C135+'DCA-Anexo I-G'!C143+'DCA-Anexo I-G'!C149+'DCA-Anexo I-G'!C157+'DCA-Anexo I-G'!C162+'DCA-Anexo I-G'!C170+'DCA-Anexo I-G'!C178+'DCA-Anexo I-G'!C183+'DCA-Anexo I-G'!C190+'DCA-Anexo I-G'!C198+'DCA-Anexo I-G'!C204 -> 20650.4 | D19: =+'DCA-Anexo I-G'!D20+'DCA-Anexo I-G'!D25+'DCA-Anexo I-G'!D30+'DCA-Anexo I-G'!D35+'DCA-Anexo I-G'!D48+'DCA-Anexo I-G'!D54+'DCA-Anexo I-G'!D60+'DCA-Anexo I-G'!D65+'DCA-Anexo I-G'!D74+'DCA-Anexo I-G'!D81+'DCA-Anexo I-G'!D90+'DCA-Anexo I-G'!D97+'DCA-Anexo I-G'!D108+'DCA-Anexo I-G'!D113+'DCA-Anexo I-G'!D119+'DCA-Anexo I-G'!D125+'DCA-Anexo I-G'!D130+'DCA-Anexo I-G'!D135+'DCA-Anexo I-G'!D143+'DCA-Anexo I-G'!D149+'DCA-Anexo I-G'!D157+'DCA-Anexo I-G'!D162+'DCA-Anexo I-G'!D170+'DCA-Anexo I-G'!D178+'DCA-Anexo I-G'!D183+'DCA-Anexo I-G'!D190+'DCA-Anexo I-G'!D198+'DCA-Anexo I-G'!D204 -> 20650.4 | E19: =+'DCA-Anexo I-G'!E20+'DCA-Anexo I-G'!E25+'DCA-Anexo I-G'!E30+'DCA-Anexo I-G'!E35+'DCA-Anexo I-G'!E48+'DCA-Anexo I-G'!E54+'DCA-Anexo I-G'!E60+'DCA-Anexo I-G'!E65+'DCA-Anexo I-G'!E74+'DCA-Anexo I-G'!E81+'DCA-Anexo I-G'!E90+'DCA-Anexo I-G'!E97+'DCA-Anexo I-G'!E108+'DCA-Anexo I-G'!E113+'DCA-Anexo I-G'!E119+'DCA-Anexo I-G'!E125+'DCA-Anexo I-G'!E130+'DCA-Anexo I-G'!E135+'DCA-Anexo I-G'!E143+'DCA-Anexo I-G'!E149+'DCA-Anexo I-G'!E157+'DCA-Anexo I-G'!E162+'DCA-Anexo I-G'!E170+'DCA-Anexo I-G'!E178+'DCA-Anexo I-G'!E183+'DCA-Anexo I-G'!E190+'DCA-Anexo I-G'!E198+'DCA-Anexo I-G'!E204 -> 20650.4 | F19: =+'DCA-Anexo I-G'!F20+'DCA-Anexo I-G'!F25+'DCA-Anexo I-G'!F30+'DCA-Anexo I-G'!F35+'DCA-Anexo I-G'!F48+'DCA-Anexo I-G'!F54+'DCA-Anexo I-G'!F60+'DCA-Anexo I-G'!F65+'DCA-Anexo I-G'!F74+'DCA-Anexo I-G'!F81+'DCA-Anexo I-G'!F90+'DCA-Anexo I-G'!F97+'DCA-Anexo I-G'!F108+'DCA-Anexo I-G'!F113+'DCA-Anexo I-G'!F119+'DCA-Anexo I-G'!F125+'DCA-Anexo I-G'!F130+'DCA-Anexo I-G'!F135+'DCA-Anexo I-G'!F143+'DCA-Anexo I-G'!F149+'DCA-Anexo I-G'!F157+'DCA-Anexo I-G'!F162+'DCA-Anexo I-G'!F170+'DCA-Anexo I-G'!F178+'DCA-Anexo I-G'!F183+'DCA-Anexo I-G'!F190+'DCA-Anexo I-G'!F198+'DCA-Anexo I-G'!F204 -> 0 | G19: =+'DCA-Anexo I-G'!G20+'DCA-Anexo I-G'!G25+'DCA-Anexo I-G'!G30+'DCA-Anexo I-G'!G35+'DCA-Anexo I-G'!G48+'DCA-Anexo I-G'!G54+'DCA-Anexo I-G'!G60+'DCA-Anexo I-G'!G65+'DCA-Anexo I-G'!G74+'DCA-Anexo I-G'!G81+'DCA-Anexo I-G'!G90+'DCA-Anexo I-G'!G97+'DCA-Anexo I-G'!G108+'DCA-Anexo I-G'!G113+'DCA-Anexo I-G'!G119+'DCA-Anexo I-G'!G125+'DCA-Anexo I-G'!G130+'DCA-Anexo I-G'!G135+'DCA-Anexo I-G'!G143+'DCA-Anexo I-G'!G149+'DCA-Anexo I-G'!G157+'DCA-Anexo I-G'!G162+'DCA-Anexo I-G'!G170+'DCA-Anexo I-G'!G178+'DCA-Anexo I-G'!G183+'DCA-Anexo I-G'!G190+'DCA-Anexo I-G'!G198+'DCA-Anexo I-G'!G204 -> 678963.1 | H19: =+'DCA-Anexo I-G'!H20+'DCA-Anexo I-G'!H25+'DCA-Anexo I-G'!H30+'DCA-Anexo I-G'!H35+'DCA-Anexo I-G'!H48+'DCA-Anexo I-G'!H54+'DCA-Anexo I-G'!H60+'DCA-Anexo I-G'!H65+'DCA-Anexo I-G'!H74+'DCA-Anexo I-G'!H81+'DCA-Anexo I-G'!H90+'DCA-Anexo I-G'!H97+'DCA-Anexo I-G'!H108+'DCA-Anexo I-G'!H113+'DCA-Anexo I-G'!H119+'DCA-Anexo I-G'!H125+'DCA-Anexo I-G'!H130+'DCA-Anexo I-G'!H135+'DCA-Anexo I-G'!H143+'DCA-Anexo I-G'!H149+'DCA-Anexo I-G'!H157+'DCA-Anexo I-G'!H162+'DCA-Anexo I-G'!H170+'DCA-Anexo I-G'!H178+'DCA-Anexo I-G'!H183+'DCA-Anexo I-G'!H190+'DCA-Anexo I-G'!H198+'DCA-Anexo I-G'!H204 -> 513963.84 | I19: =+'DCA-Anexo I-G'!I20+'DCA-Anexo I-G'!I25+'DCA-Anexo I-G'!I30+'DCA-Anexo I-G'!I35+'DCA-Anexo I-G'!I48+'DCA-Anexo I-G'!I54+'DCA-Anexo I-G'!I60+'DCA-Anexo I-G'!I65+'DCA-Anexo I-G'!I74+'DCA-Anexo I-G'!I81+'DCA-Anexo I-G'!I90+'DCA-Anexo I-G'!I97+'DCA-Anexo I-G'!I108+'DCA-Anexo I-G'!I113+'DCA-Anexo I-G'!I119+'DCA-Anexo I-G'!I125+'DCA-Anexo I-G'!I130+'DCA-Anexo I-G'!I135+'DCA-Anexo I-G'!I143+'DCA-Anexo I-G'!I149+'DCA-Anexo I-G'!I157+'DCA-Anexo I-G'!I162+'DCA-Anexo I-G'!I170+'DCA-Anexo I-G'!I178+'DCA-Anexo I-G'!I183+'DCA-Anexo I-G'!I190+'DCA-Anexo I-G'!I198+'DCA-Anexo I-G'!I204 -> 511422.29 | J19: =+'DCA-Anexo I-G'!J20+'DCA-Anexo I-G'!J25+'DCA-Anexo I-G'!J30+'DCA-Anexo I-G'!J35+'DCA-Anexo I-G'!J48+'DCA-Anexo I-G'!J54+'DCA-Anexo I-G'!J60+'DCA-Anexo I-G'!J65+'DCA-Anexo I-G'!J74+'DCA-Anexo I-G'!J81+'DCA-Anexo I-G'!J90+'DCA-Anexo I-G'!J97+'DCA-Anexo I-G'!J108+'DCA-Anexo I-G'!J113+'DCA-Anexo I-G'!J119+'DCA-Anexo I-G'!J125+'DCA-Anexo I-G'!J130+'DCA-Anexo I-G'!J135+'DCA-Anexo I-G'!J143+'DCA-Anexo I-G'!J149+'DCA-Anexo I-G'!J157+'DCA-Anexo I-G'!J162+'DCA-Anexo I-G'!J170+'DCA-Anexo I-G'!J178+'DCA-Anexo I-G'!J183+'DCA-Anexo I-G'!J190+'DCA-Anexo I-G'!J198+'DCA-Anexo I-G'!J204 -> 0
A20: 01 - Legislativa | B20: =+'DCA-Anexo I-G'!B21+'DCA-Anexo I-G'!B22+'DCA-Anexo I-G'!B24+'DCA-Anexo I-G'!B23 -> 0 | C20: =+'DCA-Anexo I-G'!C21+'DCA-Anexo I-G'!C22+'DCA-Anexo I-G'!C24+'DCA-Anexo I-G'!C23 -> 0 | D20: =+'DCA-Anexo I-G'!D21+'DCA-Anexo I-G'!D22+'DCA-Anexo I-G'!D24+'DCA-Anexo I-G'!D23 -> 0 | E20: =+'DCA-Anexo I-G'!E21+'DCA-Anexo I-G'!E22+'DCA-Anexo I-G'!E24+'DCA-Anexo I-G'!E23 -> 0 | F20: =+'DCA-Anexo I-G'!F21+'DCA-Anexo I-G'!F22+'DCA-Anexo I-G'!F24+'DCA-Anexo I-G'!F23 -> 0 | G20: =+'DCA-Anexo I-G'!G21+'DCA-Anexo I-G'!G22+'DCA-Anexo I-G'!G24+'DCA-Anexo I-G'!G23 -> 0 | H20: =+'DCA-Anexo I-G'!H21+'DCA-Anexo I-G'!H22+'DCA-Anexo I-G'!H24+'DCA-Anexo I-G'!H23 -> 0 | I20: =+'DCA-Anexo I-G'!I21+'DCA-Anexo I-G'!I22+'DCA-Anexo I-G'!I24+'DCA-Anexo I-G'!I23 -> 0 | J20: =+'DCA-Anexo I-G'!J21+'DCA-Anexo I-G'!J22+'DCA-Anexo I-G'!J24+'DCA-Anexo I-G'!J23 -> 0
A21: 01.031 - Ação Legislativa
A22: 01.032 - Controle Externo
A23: 01.122 - Administração Geral
A24: FU01 - Demais Subfunções
A25: 02 - Judiciária | B25: =+'DCA-Anexo I-G'!B26+'DCA-Anexo I-G'!B27+'DCA-Anexo I-G'!B29+'DCA-Anexo I-G'!B28 -> 0 | C25: =+'DCA-Anexo I-G'!C26+'DCA-Anexo I-G'!C27+'DCA-Anexo I-G'!C29+'DCA-Anexo I-G'!C28 -> 0 | D25: =+'DCA-Anexo I-G'!D26+'DCA-Anexo I-G'!D27+'DCA-Anexo I-G'!D29+'DCA-Anexo I-G'!D28 -> 0 | E25: =+'DCA-Anexo I-G'!E26+'DCA-Anexo I-G'!E27+'DCA-Anexo I-G'!E29+'DCA-Anexo I-G'!E28 -> 0 | F25: =+'DCA-Anexo I-G'!F26+'DCA-Anexo I-G'!F27+'DCA-Anexo I-G'!F29+'DCA-Anexo I-G'!F28 -> 0 | G25: =+'DCA-Anexo I-G'!G26+'DCA-Anexo I-G'!G27+'DCA-Anexo I-G'!G29+'DCA-Anexo I-G'!G28 -> 0 | H25: =+'DCA-Anexo I-G'!H26+'DCA-Anexo I-G'!H27+'DCA-Anexo I-G'!H29+'DCA-Anexo I-G'!H28 -> 0 | I25: =+'DCA-Anexo I-G'!I26+'DCA-Anexo I-G'!I27+'DCA-Anexo I-G'!I29+'DCA-Anexo I-G'!I28 -> 0 | J25: =+'DCA-Anexo I-G'!J26+'DCA-Anexo I-G'!J27+'DCA-Anexo I-G'!J29+'DCA-Anexo I-G'!J28 -> 0
A26: 02.061 - Ação Judiciária
A27: 02.062 - Defesa do Interesse Público no Processo Judiciário
A28: 02.122 - Administração Geral
A29: FU02 - Demais Subfunções
A30: 03 - Essencial à Justiça | B30: =+'DCA-Anexo I-G'!B31+'DCA-Anexo I-G'!B32+'DCA-Anexo I-G'!B34+'DCA-Anexo I-G'!B33 -> 0 | C30: =+'DCA-Anexo I-G'!C31+'DCA-Anexo I-G'!C32+'DCA-Anexo I-G'!C34+'DCA-Anexo I-G'!C33 -> 0 | D30: =+'DCA-Anexo I-G'!D31+'DCA-Anexo I-G'!D32+'DCA-Anexo I-G'!D34+'DCA-Anexo I-G'!D33 -> 0 | E30: =+'DCA-Anexo I-G'!E31+'DCA-Anexo I-G'!E32+'DCA-Anexo I-G'!E34+'DCA-Anexo I-G'!E33 -> 0 | F30: =+'DCA-Anexo I-G'!F31+'DCA-Anexo I-G'!F32+'DCA-Anexo I-G'!F34+'DCA-Anexo I-G'!F33 -> 0 | G30: =+'DCA-Anexo I-G'!G31+'DCA-Anexo I-G'!G32+'DCA-Anexo I-G'!G34+'DCA-Anexo I-G'!G33 -> 0 | H30: =+'DCA-Anexo I-G'!H31+'DCA-Anexo I-G'!H32+'DCA-Anexo I-G'!H34+'DCA-Anexo I-G'!H33 -> 0 | I30: =+'DCA-Anexo I-G'!I31+'DCA-Anexo I-G'!I32+'DCA-Anexo I-G'!I34+'DCA-Anexo I-G'!I33 -> 0 | J30: =+'DCA-Anexo I-G'!J31+'DCA-Anexo I-G'!J32+'DCA-Anexo I-G'!J34+'DCA-Anexo I-G'!J33 -> 0
A31: 03.091 - Defesa da Ordem Jurídica
A32: 03.092 - Representação Judicial e Extrajudicial
A33: 03.122 - Administração Geral
A34: FU03 - Demais Subfunções
A35: 04 - Administração | B35: =+'DCA-Anexo I-G'!B36+'DCA-Anexo I-G'!B37+'DCA-Anexo I-G'!B38+'DCA-Anexo I-G'!B39+'DCA-Anexo I-G'!B40+'DCA-Anexo I-G'!B41+'DCA-Anexo I-G'!B42+'DCA-Anexo I-G'!B43+'DCA-Anexo I-G'!B44+'DCA-Anexo I-G'!B45+'DCA-Anexo I-G'!B46+'DCA-Anexo I-G'!B47 -> 62175.76 | C35: =+'DCA-Anexo I-G'!C36+'DCA-Anexo I-G'!C37+'DCA-Anexo I-G'!C38+'DCA-Anexo I-G'!C39+'DCA-Anexo I-G'!C40+'DCA-Anexo I-G'!C41+'DCA-Anexo I-G'!C42+'DCA-Anexo I-G'!C43+'DCA-Anexo I-G'!C44+'DCA-Anexo I-G'!C45+'DCA-Anexo I-G'!C46+'DCA-Anexo I-G'!C47 -> 20650.4 | D35: =+'DCA-Anexo I-G'!D36+'DCA-Anexo I-G'!D37+'DCA-Anexo I-G'!D38+'DCA-Anexo I-G'!D39+'DCA-Anexo I-G'!D40+'DCA-Anexo I-G'!D41+'DCA-Anexo I-G'!D42+'DCA-Anexo I-G'!D43+'DCA-Anexo I-G'!D44+'DCA-Anexo I-G'!D45+'DCA-Anexo I-G'!D46+'DCA-Anexo I-G'!D47 -> 20650.4 | E35: =+'DCA-Anexo I-G'!E36+'DCA-Anexo I-G'!E37+'DCA-Anexo I-G'!E38+'DCA-Anexo I-G'!E39+'DCA-Anexo I-G'!E40+'DCA-Anexo I-G'!E41+'DCA-Anexo I-G'!E42+'DCA-Anexo I-G'!E43+'DCA-Anexo I-G'!E44+'DCA-Anexo I-G'!E45+'DCA-Anexo I-G'!E46+'DCA-Anexo I-G'!E47 -> 20650.4 | F35: =+'DCA-Anexo I-G'!F36+'DCA-Anexo I-G'!F37+'DCA-Anexo I-G'!F38+'DCA-Anexo I-G'!F39+'DCA-Anexo I-G'!F40+'DCA-Anexo I-G'!F41+'DCA-Anexo I-G'!F42+'DCA-Anexo I-G'!F43+'DCA-Anexo I-G'!F44+'DCA-Anexo I-G'!F45+'DCA-Anexo I-G'!F46+'DCA-Anexo I-G'!F47 -> 0 | G35: =+'DCA-Anexo I-G'!G36+'DCA-Anexo I-G'!G37+'DCA-Anexo I-G'!G38+'DCA-Anexo I-G'!G39+'DCA-Anexo I-G'!G40+'DCA-Anexo I-G'!G41+'DCA-Anexo I-G'!G42+'DCA-Anexo I-G'!G43+'DCA-Anexo I-G'!G44+'DCA-Anexo I-G'!G45+'DCA-Anexo I-G'!G46+'DCA-Anexo I-G'!G47 -> 678963.1 | H35: =+'DCA-Anexo I-G'!H36+'DCA-Anexo I-G'!H37+'DCA-Anexo I-G'!H38+'DCA-Anexo I-G'!H39+'DCA-Anexo I-G'!H40+'DCA-Anexo I-G'!H41+'DCA-Anexo I-G'!H42+'DCA-Anexo I-G'!H43+'DCA-Anexo I-G'!H44+'DCA-Anexo I-G'!H45+'DCA-Anexo I-G'!H46+'DCA-Anexo I-G'!H47 -> 513963.84 | I35: =+'DCA-Anexo I-G'!I36+'DCA-Anexo I-G'!I37+'DCA-Anexo I-G'!I38+'DCA-Anexo I-G'!I39+'DCA-Anexo I-G'!I40+'DCA-Anexo I-G'!I41+'DCA-Anexo I-G'!I42+'DCA-Anexo I-G'!I43+'DCA-Anexo I-G'!I44+'DCA-Anexo I-G'!I45+'DCA-Anexo I-G'!I46+'DCA-Anexo I-G'!I47 -> 511422.29 | J35: =+'DCA-Anexo I-G'!J36+'DCA-Anexo I-G'!J37+'DCA-Anexo I-G'!J38+'DCA-Anexo I-G'!J39+'DCA-Anexo I-G'!J40+'DCA-Anexo I-G'!J41+'DCA-Anexo I-G'!J42+'DCA-Anexo I-G'!J43+'DCA-Anexo I-G'!J44+'DCA-Anexo I-G'!J45+'DCA-Anexo I-G'!J46+'DCA-Anexo I-G'!J47 -> 0
A36: 04.121 - Planejamento e Orçamento
A37: 04.122 - Administração Geral | B37: 62175.76 | C37: 20650.4 | D37: 20650.4 | E37: 20650.4 | F37: 0 | G37: 678963.1 | H37: 513963.84 | I37: 511422.29 | J37: 0
A38: 04.123 - Administração Financeira
A39: 04.124 - Controle Interno
A40: 04.125 - Normatização e Fiscalização
A41: 04.126 - Tecnologia da Informação
A42: 04.127 - Ordenamento Territorial
A43: 04.128 - Formação de Recursos Humanos
...

Sheet DCA-Anexo I-HI
A2: QDCC
A3: BALANÇO ANUAL (DCA)
A4: VERSÃO: v14
A5: VIGÊNCIA: 05/01/2026
A7: Ente: 2908101 - Cocos/BA
A8: Poder: E - Executivo
A9: Instituição: 4063 - Prefeitura Municipal de Cocos - BA
A10: Exercício: 2025
A11: Periodicidade: ANUAL
A12: Período: Período único (anual)
A14: Grupo: Demonstrativo das Variações Patrimoniais Quantitativas e Resultado Patrimonial do Período
A15: Quadro: Demonstrativo das Variações Patrimoniais e Resultado Patrimonial
A16: Rótulo: Padrão
A17: Demonstrativo das Variações Patrimoniais e Resultado Patrimonial | B17: Valores
B18: 31/12/2025
A19: Variação Patrimonial Diminutiva
A20: Variação Patrimonial Diminutiva
A21: 3.0.0.0.0.00.00 - Variação Patrimonial Diminutiva | B21: =+'DCA-Anexo I-HI'!B22+'DCA-Anexo I-HI'!B302+'DCA-Anexo I-HI'!B360+'DCA-Anexo I-HI'!B493+'DCA-Anexo I-HI'!B131+'DCA-Anexo I-HI'!B80+'DCA-Anexo I-HI'!B426+'DCA-Anexo I-HI'!B165+'DCA-Anexo I-HI'!B471 -> 1.9104898e+08
A22: 3.1.0.0.0.00.00 - Pessoal e Encargos | B22: =+'DCA-Anexo I-HI'!B23+'DCA-Anexo I-HI'!B58+'DCA-Anexo I-HI'!B31+'DCA-Anexo I-HI'!B65 -> 59168230
A23: 3.1.1.0.0.00.00 - Remuneração a Pessoal | B23: =+'DCA-Anexo I-HI'!B24+'DCA-Anexo I-HI'!B27+'DCA-Anexo I-HI'!B29 -> 53305380
A24: 3.1.1.1.0.00.00 - Remuneração a Pessoal Ativo Civil – Abrangidos pelo RPPS | B24: =+'DCA-Anexo I-HI'!B25+'DCA-Anexo I-HI'!B26 -> 53305380
A25: 3.1.1.1.1.00.00 - Remuneração a Pessoal Ativo Civil – Abrangidos pelo RPPS - Consolidação | B25: 53305380
A26: 3.1.1.1.2.00.00 - Remuneração a Pessoal Ativo Civil – Abrangidos pelo RPPS - Intra OFSS | B26: 0
A27: 3.1.1.2.0.00.00 - Remuneração a Pessoal Ativo Civil - Abrangidos pelo RGPS | B27: =+'DCA-Anexo I-HI'!B28 -> 0
A28: 3.1.1.2.1.00.00 - Remuneração a Pessoal Ativo Civil - Abrangidos pelo RGPS - Consolidação | B28: 0
A29: 3.1.1.3.0.00.00 - Remuneração a Pessoal Ativo Militar | B29: =+'DCA-Anexo I-HI'!B30 -> 0
A30: 3.1.1.3.1.00.00 - Remuneração a Pessoal Ativo Militar - Consolidação | B30: 0
A31: 3.1.2.0.0.00.00 - Encargos Patronais | B31: =+'DCA-Anexo I-HI'!B32+'DCA-Anexo I-HI'!B52+'DCA-Anexo I-HI'!B43+'DCA-Anexo I-HI'!B49+'DCA-Anexo I-HI'!B37+'DCA-Anexo I-HI'!B41 -> 5842845.2
A32: 3.1.2.1.0.00.00 - Encargos Patronais - RPPS | B32: =+'DCA-Anexo I-HI'!B33+'DCA-Anexo I-HI'!B35+'DCA-Anexo I-HI'!B34+'DCA-Anexo I-HI'!B36 -> 0
A33: 3.1.2.1.2.00.00 - Encargos Patronais - RPPS - Intra OFSS | B33: 0
A34: 3.1.2.1.3.00.00 - Encargos Patronais - RPPS - Inter OFSS - União | B34: 0
A35: 3.1.2.1.4.00.00 - Encargos Patronais - RPPS - Inter OFSS - Estado | B35: 0
A36: 3.1.2.1.5.00.00 - Encargos Patronais - RPPS - Inter OFSS - Município | B36: 0
A37: 3.1.2.2.0.00.00 - Encargos Patronais - RGPS | B37: =+'DCA-Anexo I-HI'!B38+'DCA-Anexo I-HI'!B39+'DCA-Anexo I-HI'!B40 -> 5842845.2
A38: 3.1.2.2.1.00.00 - Encargos Patronais - RGPS - Consolidação | B38: 0
A39: 3.1.2.2.2.00.00 - Encargos Patronais - RGPS - Intra OFSS | B39: 0
A40: 3.1.2.2.3.00.00 - Encargos Patronais - RGPS - Inter OFSS - União | B40: 5842845.2
A41: 3.1.2.3.0.00.00 - Encargos Patronais - FGTS | B41: =+'DCA-Anexo I-HI'!B42 -> 0
A42: 3.1.2.3.1.00.00 - Encargos Patronais - FGTS - Consolidação | B42: 0
A43: 3.1.2.4.0.00.00 - Contribuições Sociais Gerais | B43: =+'DCA-Anexo I-HI'!B44+'DCA-Anexo I-HI'!B45+'DCA-Anexo I-HI'!B46+'DCA-Anexo I-HI'!B47+'DCA-Anexo I-HI'!B48 -> 0
...
